Workbook

Sheet COVERAGE
A1: Reconnaissance | B1: {=SUM(IF(B2:B200<>"",B2:B200,0))/SUM(IF(A2:A200<>"",1,0))} -> 0.033333333 | C1: Resource Development | D1: {=SUM(IF(D2:D200<>"",D2:D200,0))/SUM(IF(C2:C200<>"",1,0))} -> 0 | E1: Initial Access | F1: {=SUM(IF(F2:F200<>"",F2:F200,0))/SUM(IF(E2:E200<>"",1,0))} -> 0 | G1: Execution | H1: {=SUM(IF(H2:H200<>"",H2:H200,0))/SUM(IF(G2:G200<>"",1,0))} -> 0.0064935065 | I1: Persistence | J1: {=SUM(IF(J2:J200<>"",J2:J200,0))/SUM(IF(I2:I200<>"",1,0))} -> 0 | K1: Privilege Escalation | L1: {=SUM(IF(L2:L200<>"",L2:L200,0))/SUM(IF(K2:K200<>"",1,0))} -> 0 | M1: Defense Evasion | N1: {=SUM(IF(N2:N200<>"",N2:N200,0))/SUM(IF(M2:M200<>"",1,0))} -> 0.026623377 | O1: Credential Access | P1: {=SUM(IF(P2:P200<>"",P2:P200,0))/SUM(IF(O2:O200<>"",1,0))} -> 0.014705882 | Q1: Discovery | R1: {=SUM(IF(R2:R200<>"",R2:R200,0))/SUM(IF(Q2:Q200<>"",1,0))} -> 0.046875 | S1: Lateral Movement | T1: {=SUM(IF(T2:T200<>"",T2:T200,0))/SUM(IF(S2:S200<>"",1,0))} -> 0 | U1: Collection | V1: {=SUM(IF(V2:V200<>"",V2:V200,0))/SUM(IF(U2:U200<>"",1,0))} -> 0 | W1: Command and Control | X1: {=SUM(IF(X2:X200<>"",X2:X200,0))/SUM(IF(W2:W200<>"",1,0))} -> 0 | Y1: Exfiltration | Z1: {=SUM(IF(Z2:Z200<>"",Z2:Z200,0))/SUM(IF(Y2:Y200<>"",1,0))} -> 0.11111111 | AA1: Impact | AB1: {=SUM(IF(AB2:AB200<>"",AB2:AB200,0))/SUM(IF(AA2:AA200<>"",1,0))} -> 0
A2: Active Scanning (T1595) | B2: =IF(A2<>"",IF(INDEX(Techniques[Coverage],MATCH(A2,Techniques[Name],0))>0,INDEX(Techniques[Coverage],MATCH(A2,Techniques[Name],0)),""),"") -> 0.33333333 | C2: Acquire Access (T1650) | D2: =IF(C2<>"",IF(INDEX(Techniques[Coverage],MATCH(C2,Techniques[Name],0))>0,INDEX(Techniques[Coverage],MATCH(C2,Techniques[Name],0)),""),"") | E2: Content Injection (T1659) | F2: =IF(E2<>"",IF(INDEX(Techniques[Coverage],MATCH(E2,Techniques[Name],0))>0,INDEX(Techniques[Coverage],MATCH(E2,Techniques[Name],0)),""),"") | G2: Cloud Administration Command (T1651) | H2: =IF(G2<>"",IF(INDEX(Techniques[Coverage],MATCH(G2,Techniques[Name],0))>0,INDEX(Techniques[Coverage],MATCH(G2,Techniques[Name],0)),""),"") | I2: Account Manipulation (T1098) | J2: =IF(I2<>"",IF(INDEX(Techniques[Coverage],MATCH(I2,Techniques[Name],0))>0,INDEX(Techniques[Coverage],MATCH(I2,Techniques[Name],0)),""),"") | K2: Abuse Elevation Control Mechanism (T1548) | L2: =IF(K2<>"",IF(INDEX(Techniques[Coverage],MATCH(K2,Techniques[Name],0))>0,INDEX(Techniques[Coverage],MATCH(K2,Techniques[Name],0)),""),"") | M2: Abuse Elevation Control Mechanism (T1548) | N2: =IF(M2<>"",IF(INDEX(Techniques[Coverage],MATCH(M2,Techniques[Name],0))>0,INDEX(Techniques[Coverage],MATCH(M2,Techniques[Name],0)),""),"") | O2: Adversary-in-the-Middle (T1557) | P2: =IF(O2<>"",IF(INDEX(Techniques[Coverage],MATCH(O2,Techniques[Name],0))>0,INDEX(Techniques[Coverage],MATCH(O2,Techniques[Name],0)),""),"") | Q2: Account Discovery (T1087) | R2: =IF(Q2<>"",IF(INDEX(Techniques[Coverage],MATCH(Q2,Techniques[Name],0))>0,INDEX(Techniques[Coverage],MATCH(Q2,Techniques[Name],0)),""),"") | S2: Exploitation of Remote Services (T1210) | T2: =IF(S2<>"",IF(INDEX(Techniques[Coverage],MATCH(S2,Techniques[Name],0))>0,INDEX(Techniques[Coverage],MATCH(S2,Techniques[Name],0)),""),"") | U2: Adversary-in-the-Middle (T1557) | V2: =IF(U2<>"",IF(INDEX(Techniques[Coverage],MATCH(U2,Techniques[Name],0))>0,INDEX(Techniques[Coverage],MATCH(U2,Techniques[Name],0)),""),"") | W2: Application Layer Protocol (T1071) | X2: =IF(W2<>"",IF(INDEX(Techniques[Coverage],MATCH(W2,Techniques[Name],0))>0,INDEX(Techniques[Coverage],MATCH(W2,Techniques[Name],0)),""),"") | Y2: Automated Exfiltration (T1020) | Z2: =IF(Y2<>"",IF(INDEX(Techniques[Coverage],MATCH(Y2,Techniques[Name],0))>0,INDEX(Techniques[Coverage],MATCH(Y2,Techniques[Name],0)),""),"") -> 1 | AA2: Account Access Removal (T1531) | AB2: =IF(AA2<>"",IF(INDEX(Techniques[Coverage],MATCH(AA2,Techniques[Name],0))>0,INDEX(Techniques[Coverage],MATCH(AA2,Techniques[Name],0)),""),"")
A3: Gather Victim Host Information (T1592) | B3: =IF(A3<>"",IF(INDEX(Techniques[Coverage],MATCH(A3,Techniques[Name],0))>0,INDEX(Techniques[Coverage],MATCH(A3,Techniques[Name],0)),""),"") | C3: Acquire Infrastructure (T1583) | D3: =IF(C3<>"",IF(INDEX(Techniques[Coverage],MATCH(C3,Techniques[Name],0))>0,INDEX(Techniques[Coverage],MATCH(C3,Techniques[Name],0)),""),"") | E3: Drive-by Compromise (T1189) | F3: =IF(E3<>"",IF(INDEX(Techniques[Coverage],MATCH(E3,Techniques[Name],0))>0,INDEX(Techniques[Coverage],MATCH(E3,Techniques[Name],0)),""),"") | G3: Command and Scripting Interpreter (T1059) | H3: =IF(G3<>"",IF(INDEX(Techniques[Coverage],MATCH(G3,Techniques[Name],0))>0,INDEX(Techniques[Coverage],MATCH(G3,Techniques[Name],0)),""),"") -> 0.090909091 | I3: BITS Jobs (T1197) | J3: =IF(I3<>"",IF(INDEX(Techniques[Coverage],MATCH(I3,Techniques[Name],0))>0,INDEX(Techniques[Coverage],MATCH(I3,Techniques[Name],0)),""),"") | K3: Access Token Manipulation (T1134) | L3: =IF(K3<>"",IF(INDEX(Techniques[Coverage],MATCH(K3,Techniques[Name],0))>0,INDEX(Techniques[Coverage],MATCH(K3,Techniques[Name],0)),""),"") | M3: Access Token Manipulation (T1134) | N3: =IF(M3<>"",IF(INDEX(Techniques[Coverage],MATCH(M3,Techniques[Name],0))>0,INDEX(Techniques[Coverage],MATCH(M3,Techniques[Name],0)),""),"") | O3: Brute Force (T1110) | P3: =IF(O3<>"",IF(INDEX(Techniques[Coverage],MATCH(O3,Techniques[Name],0))>0,INDEX(Techniques[Coverage],MATCH(O3,Techniques[Name],0)),""),"") | Q3: Application Window Discovery (T1010) | R3: =IF(Q3<>"",IF(INDEX(Techniques[Coverage],MATCH(Q3,Techniques[Name],0))>0,INDEX(Techniques[Coverage],MATCH(Q3,Techniques[Name],0)),""),"") -> 1 | S3: Internal Spearphishing (T1534) | T3: =IF(S3<>"",IF(INDEX(Techniques[Coverage],MATCH(S3,Techniques[Name],0))>0,INDEX(Techniques[Coverage],MATCH(S3,Techniques[Name],0)),""),"") | U3: Archive Collected Data (T1560) | V3: =IF(U3<>"",IF(INDEX(Techniques[Coverage],MATCH(U3,Techniques[Name],0))>0,INDEX(Techniques[Coverage],MATCH(U3,Techniques[Name],0)),""),"") | W3: Communication Through Removable Media (T1092) | X3: =IF(W3<>"",IF(INDEX(Techniques[Coverage],MATCH(W3,Techniques[Name],0))>0,INDEX(Techniques[Coverage],MATCH(W3,Techniques[Name],0)),""),"") | Y3: Data Transfer Size Limits (T1030) | Z3: =IF(Y3<>"",IF(INDEX(Techniques[Coverage],MATCH(Y3,Techniques[Name],0))>0,INDEX(Techniques[Coverage],MATCH(Y3,Techniques[Name],0)),""),"") | AA3: Data Destruction (T1485) | AB3: =IF(AA3<>"",IF(INDEX(Techniques[Coverage],MATCH(AA3,Techniques[Name],0))>0,INDEX(Techniques[Coverage],MATCH(AA3,Techniques[Name],0)),""),"")
A4: Gather Victim Identity Information (T1589) | B4: =IF(A4<>"",IF(INDEX(Techniques[Coverage],MATCH(A4,Techniques[Name],0))>0,INDEX(Techniques[Coverage],MATCH(A4,Techniques[Name],0)),""),"") | C4: Compromise Accounts (T1586) | D4: =IF(C4<>"",IF(INDEX(Techniques[Coverage],MATCH(C4,Techniques[Name],0))>0,INDEX(Techniques[Coverage],MATCH(C4,Techniques[Name],0)),""),"") | E4: Exploit Public-Facing Application (T1190) | F4: =IF(E4<>"",IF(INDEX(Techniques[Coverage],MATCH(E4,Techniques[Name],0))>0,INDEX(Techniques[Coverage],MATCH(E4,Techniques[Name],0)),""),"") | G4: Container Administration Command (T1609) | H4: =IF(G4<>"",IF(INDEX(Techniques[Coverage],MATCH(G4,Techniques[Name],0))>0,INDEX(Techniques[Coverage],MATCH(G4,Techniques[Name],0)),""),"") | I4: Boot or Logon Autostart Execution (T1547) | J4: =IF(I4<>"",IF(INDEX(Techniques[Coverage],MATCH(I4,Techniques[Name],0))>0,INDEX(Techniques[Coverage],MATCH(I4,Techniques[Name],0)),""),"") | K4: Account Manipulation (T1098) | L4: =IF(K4<>"",IF(INDEX(Techniques[Coverage],MATCH(K4,Techniques[Name],0))>0,INDEX(Techniques[Coverage],MATCH(K4,Techniques[Name],0)),""),"") | M4: BITS Jobs (T1197) | N4: =IF(M4<>"",IF(INDEX(Techniques[Coverage],MATCH(M4,Techniques[Name],0))>0,INDEX(Techniques[Coverage],MATCH(M4,Techniques[Name],0)),""),"") | O4: Credentials from Password Stores (T1555) | P4: =IF(O4<>"",IF(INDEX(Techniques[Coverage],MATCH(O4,Techniques[Name],0))>0,INDEX(Techniques[Coverage],MATCH(O4,Techniques[Name],0)),""),"") | Q4: Browser Information Discovery (T1217) | R4: =IF(Q4<>"",IF(INDEX(Techniques[Coverage],MATCH(Q4,Techniques[Name],0))>0,INDEX(Techniques[Coverage],MATCH(Q4,Techniques[Name],0)),""),"") | S4: Lateral Tool Transfer (T1570) | T4: =IF(S4<>"",IF(INDEX(Techniques[Coverage],MATCH(S4,Techniques[Name],0))>0,INDEX(Techniques[Coverage],MATCH(S4,Techniques[Name],0)),""),"") | U4: Audio Capture (T1123) | V4: =IF(U4<>"",IF(INDEX(Techniques[Coverage],MATCH(U4,Techniques[Name],0))>0,INDEX(Techniques[Coverage],MATCH(U4,Techniques[Name],0)),""),"") | W4: Content Injection (T1659) | X4: =IF(W4<>"",IF(INDEX(Techniques[Coverage],MATCH(W4,Techniques[Name],0))>0,INDEX(Techniques[Coverage],MATCH(W4,Techniques[Name],0)),""),"") | Y4: Exfiltration Over Alternative Protocol (T1048) | Z4: =IF(Y4<>"",IF(INDEX(Techniques[Coverage],MATCH(Y4,Techniques[Name],0))>0,INDEX(Techniques[Coverage],MATCH(Y4,Techniques[Name],0)),""),"") | AA4: Data Encrypted for Impact (T1486) | AB4: =IF(AA4<>"",IF(INDEX(Techniques[Coverage],MATCH(AA4,Techniques[Name],0))>0,INDEX(Techniques[Coverage],MATCH(AA4,Techniques[Name],0)),""),"")
A5: Gather Victim Network Information (T1590) | B5: =IF(A5<>"",IF(INDEX(Techniques[Coverage],MATCH(A5,Techniques[Name],0))>0,INDEX(Techniques[Coverage],MATCH(A5,Techniques[Name],0)),""),"") | C5: Compromise Infrastructure (T1584) | D5: =IF(C5<>"",IF(INDEX(Techniques[Coverage],MATCH(C5,Techniques[Name],0))>0,INDEX(Techniques[Coverage],MATCH(C5,Techniques[Name],0)),""),"") | E5: External Remote Services (T1133) | F5: =IF(E5<>"",IF(INDEX(Techniques[Coverage],MATCH(E5,Techniques[Name],0))>0,INDEX(Techniques[Coverage],MATCH(E5,Techniques[Name],0)),""),"") | G5: Deploy Container (T1610) | H5: =IF(G5<>"",IF(INDEX(Techniques[Coverage],MATCH(G5,Techniques[Name],0))>0,INDEX(Techniques[Coverage],MATCH(G5,Techniques[Name],0)),""),"") | I5: Boot or Logon Initialization Scripts (T1037) | J5: =IF(I5<>"",IF(INDEX(Techniques[Coverage],MATCH(I5,Techniques[Name],0))>0,INDEX(Techniques[Coverage],MATCH(I5,Techniques[Name],0)),""),"") | K5: Boot or Logon Autostart Execution (T1547) | L5: =IF(K5<>"",IF(INDEX(Techniques[Coverage],MATCH(K5,Techniques[Name],0))>0,INDEX(Techniques[Coverage],MATCH(K5,Techniques[Name],0)),""),"") | M5: Build Image on Host (T1612) | N5: =IF(M5<>"",IF(INDEX(Techniques[Coverage],MATCH(M5,Techniques[Name],0))>0,INDEX(Techniques[Coverage],MATCH(M5,Techniques[Name],0)),""),"") | O5: Exploitation for Credential Access (T1212) | P5: =IF(O5<>"",IF(INDEX(Techniques[Coverage],MATCH(O5,Techniques[Name],0))>0,INDEX(Techniques[Coverage],MATCH(O5,Techniques[Name],0)),""),"") | Q5: Cloud Infrastructure Discovery (T1580) | R5: =IF(Q5<>"",IF(INDEX(Techniques[Coverage],MATCH(Q5,Techniques[Name],0))>0,INDEX(Techniques[Coverage],MATCH(Q5,Techniques[Name],0)),""),"") | S5: Remote Service Session Hijacking (T1563) | T5: =IF(S5<>"",IF(INDEX(Techniques[Coverage],MATCH(S5,Techniques[Name],0))>0,INDEX(Techniques[Coverage],MATCH(S5,Techniques[Name],0)),""),"") | U5: Automated Collection (T1119) | V5: =IF(U5<>"",IF(INDEX(Techniques[Coverage],MATCH(U5,Techniques[Name],0))>0,INDEX(Techniques[Coverage],MATCH(U5,Techniques[Name],0)),""),"") | W5: Data Encoding (T1132) | X5: =IF(W5<>"",IF(INDEX(Techniques[Coverage],MATCH(W5,Techniques[Name],0))>0,INDEX(Techniques[Coverage],MATCH(W5,Techniques[Name],0)),""),"") | Y5: Exfiltration Over C2 Channel (T1041) | Z5: =IF(Y5<>"",IF(INDEX(Techniques[Coverage],MATCH(Y5,Techniques[Name],0))>0,INDEX(Techniques[Coverage],MATCH(Y5,Techniques[Name],0)),""),"") | AA5: Data Manipulation (T1565) | AB5: =IF(AA5<>"",IF(INDEX(Techniques[Coverage],MATCH(AA5,Techniques[Name],0))>0,INDEX(Techniques[Coverage],MATCH(AA5,Techniques[Name],0)),""),"")
A6: Gather Victim Org Information (T1591) | B6: =IF(A6<>"",IF(INDEX(Techniques[Coverage],MATCH(A6,Techniques[Name],0))>0,INDEX(Techniques[Coverage],MATCH(A6,Techniques[Name],0)),""),"") | C6: Develop Capabilities (T1587) | D6: =IF(C6<>"",IF(INDEX(Techniques[Coverage],MATCH(C6,Techniques[Name],0))>0,INDEX(Techniques[Coverage],MATCH(C6,Techniques[Name],0)),""),"") | E6: Hardware Additions (T1200) | F6: =IF(E6<>"",IF(INDEX(Techniques[Coverage],MATCH(E6,Techniques[Name],0))>0,INDEX(Techniques[Coverage],MATCH(E6,Techniques[Name],0)),""),"") | G6: Exploitation for Client Execution (T1203) | H6: =IF(G6<>"",IF(INDEX(Techniques[Coverage],MATCH(G6,Techniques[Name],0))>0,INDEX(Techniques[Coverage],MATCH(G6,Techniques[Name],0)),""),"") | I6: Browser Extensions (T1176) | J6: =IF(I6<>"",IF(INDEX(Techniques[Coverage],MATCH(I6,Techniques[Name],0))>0,INDEX(Techniques[Coverage],MATCH(I6,Techniques[Name],0)),""),"") | K6: Boot or Logon Initialization Scripts (T1037) | L6: =IF(K6<>"",IF(INDEX(Techniques[Coverage],MATCH(K6,Techniques[Name],0))>0,INDEX(Techniques[Coverage],MATCH(K6,Techniques[Name],0)),""),"") | M6: Debugger Evasion (T1622) | N6: =IF(M6<>"",IF(INDEX(Techniques[Coverage],MATCH(M6,Techniques[Name],0))>0,INDEX(Techniques[Coverage],MATCH(M6,Techniques[Name],0)),""),"") | O6: Forced Authentication (T1187) | P6: =IF(O6<>"",IF(INDEX(Techniques[Coverage],MATCH(O6,Techniques[Name],0))>0,INDEX(Techniques[Coverage],MATCH(O6,Techniques[Name],0)),""),"") | Q6: Cloud Service Dashboard (T1538) | R6: =IF(Q6<>"",IF(INDEX(Techniques[Coverage],MATCH(Q6,Techniques[Name],0))>0,INDEX(Techniques[Coverage],MATCH(Q6,Techniques[Name],0)),""),"") | S6: Remote Services (T1021) | T6: =IF(S6<>"",IF(INDEX(Techniques[Coverage],MATCH(S6,Techniques[Name],0))>0,INDEX(Techniques[Coverage],MATCH(S6,Techniques[Name],0)),""),"") | U6: Browser Session Hijacking (T1185) | V6: =IF(U6<>"",IF(INDEX(Techniques[Coverage],MATCH(U6,Techniques[Name],0))>0,INDEX(Techniques[Coverage],MATCH(U6,Techniques[Name],0)),""),"") | W6: Data Obfuscation (T1001) | X6: =IF(W6<>"",IF(INDEX(Techniques[Coverage],MATCH(W6,Techniques[Name],0))>0,INDEX(Techniques[Coverage],MATCH(W6,Techniques[Name],0)),""),"") | Y6: Exfiltration Over Other Network Medium (T1011) | Z6: =IF(Y6<>"",IF(INDEX(Techniques[Coverage],MATCH(Y6,Techniques[Name],0))>0,INDEX(Techniques[Coverage],MATCH(Y6,Techniques[Name],0)),""),"") | AA6: Defacement (T1491) | AB6: =IF(AA6<>"",IF(INDEX(Techniques[Coverage],MATCH(AA6,Techniques[Name],0))>0,INDEX(Techniques[Coverage],MATCH(AA6,Techniques[Name],0)),""),"")
A7: Phishing for Information (T1598) | B7: =IF(A7<>"",IF(INDEX(Techniques[Coverage],MATCH(A7,Techniques[Name],0))>0,INDEX(Techniques[Coverage],MATCH(A7,Techniques[Name],0)),""),"") | C7: Establish Accounts (T1585) | D7: =IF(C7<>"",IF(INDEX(Techniques[Coverage],MATCH(C7,Techniques[Name],0))>0,INDEX(Techniques[Coverage],MATCH(C7,Techniques[Name],0)),""),"") | E7: Phishing (T1566) | F7: =IF(E7<>"",IF(INDEX(Techniques[Coverage],MATCH(E7,Techniques[Name],0))>0,INDEX(Techniques[Coverage],MATCH(E7,Techniques[Name],0)),""),"") | G7: Inter-Process Communication (T1559) | H7: =IF(G7<>"",IF(INDEX(Techniques[Coverage],MATCH(G7,Techniques[Name],0))>0,INDEX(Techniques[Coverage],MATCH(G7,Techniques[Name],0)),""),"") | I7: Compromise Host Software Binary (T1554) | J7: =IF(I7<>"",IF(INDEX(Techniques[Coverage],MATCH(I7,Techniques[Name],0))>0,INDEX(Techniques[Coverage],MATCH(I7,Techniques[Name],0)),""),"") | K7: Create or Modify System Process (T1543) | L7: =IF(K7<>"",IF(INDEX(Techniques[Coverage],MATCH(K7,Techniques[Name],0))>0,INDEX(Techniques[Coverage],MATCH(K7,Techniques[Name],0)),""),"") | M7: Deobfuscate/Decode Files or Information (T1140) | N7: =IF(M7<>"",IF(INDEX(Techniques[Coverage],MATCH(M7,Techniques[Name],0))>0,INDEX(Techniques[Coverage],MATCH(M7,Techniques[Name],0)),""),"") | O7: Forge Web Credentials (T1606) | P7: =IF(O7<>"",IF(INDEX(Techniques[Coverage],MATCH(O7,Techniques[Name],0))>0,INDEX(Techniques[Coverage],MATCH(O7,Techniques[Name],0)),""),"") | Q7: Cloud Service Discovery (T1526) | R7: =IF(Q7<>"",IF(INDEX(Techniques[Coverage],MATCH(Q7,Techniques[Name],0))>0,INDEX(Techniques[Coverage],MATCH(Q7,Techniques[Name],0)),""),"") | S7: Replication Through Removable Media (T1091) | T7: =IF(S7<>"",IF(INDEX(Techniques[Coverage],MATCH(S7,Techniques[Name],0))>0,INDEX(Techniques[Coverage],MATCH(S7,Techniques[Name],0)),""),"") | U7: Clipboard Data (T1115) | V7: =IF(U7<>"",IF(INDEX(Techniques[Coverage],MATCH(U7,Techniques[Name],0))>0,INDEX(Techniques[Coverage],MATCH(U7,Techniques[Name],0)),""),"") | W7: Dynamic Resolution (T1568) | X7: =IF(W7<>"",IF(INDEX(Techniques[Coverage],MATCH(W7,Techniques[Name],0))>0,INDEX(Techniques[Coverage],MATCH(W7,Techniques[Name],0)),""),"") | Y7: Exfiltration Over Physical Medium (T1052) | Z7: =IF(Y7<>"",IF(INDEX(Techniques[Coverage],MATCH(Y7,Techniques[Name],0))>0,INDEX(Techniques[Coverage],MATCH(Y7,Techniques[Name],0)),""),"") | AA7: Disk Wipe (T1561) | AB7: =IF(AA7<>"",IF(INDEX(Techniques[Coverage],MATCH(AA7,Techniques[Name],0))>0,INDEX(Techniques[Coverage],MATCH(AA7,Techniques[Name],0)),""),"")
A8: Search Closed Sources (T1597) | B8: =IF(A8<>"",IF(INDEX(Techniques[Coverage],MATCH(A8,Techniques[Name],0))>0,INDEX(Techniques[Coverage],MATCH(A8,Techniques[Name],0)),""),"") | C8: Obtain Capabilities (T1588) | D8: =IF(C8<>"",IF(INDEX(Techniques[Coverage],MATCH(C8,Techniques[Name],0))>0,INDEX(Techniques[Coverage],MATCH(C8,Techniques[Name],0)),""),"") | E8: Replication Through Removable Media (T1091) | F8: =IF(E8<>"",IF(INDEX(Techniques[Coverage],MATCH(E8,Techniques[Name],0))>0,INDEX(Techniques[Coverage],MATCH(E8,Techniques[Name],0)),""),"") | G8: Native API (T1106) | H8: =IF(G8<>"",IF(INDEX(Techniques[Coverage],MATCH(G8,Techniques[Name],0))>0,INDEX(Techniques[Coverage],MATCH(G8,Techniques[Name],0)),""),"") | I8: Create Account (T1136) | J8: =IF(I8<>"",IF(INDEX(Techniques[Coverage],MATCH(I8,Techniques[Name],0))>0,INDEX(Techniques[Coverage],MATCH(I8,Techniques[Name],0)),""),"") | K8: Domain or Tenant Policy Modification (T1484) | L8: =IF(K8<>"",IF(INDEX(Techniques[Coverage],MATCH(K8,Techniques[Name],0))>0,INDEX(Techniques[Coverage],MATCH(K8,Techniques[Name],0)),""),"") | M8: Deploy Container (T1610) | N8: =IF(M8<>"",IF(INDEX(Techniques[Coverage],MATCH(M8,Techniques[Name],0))>0,INDEX(Techniques[Coverage],MATCH(M8,Techniques[Name],0)),""),"") | O8: Input Capture (T1056) | P8: =IF(O8<>"",IF(INDEX(Techniques[Coverage],MATCH(O8,Techniques[Name],0))>0,INDEX(Techniques[Coverage],MATCH(O8,Techniques[Name],0)),""),"") | Q8: Cloud Storage Object Discovery (T1619) | R8: =IF(Q8<>"",IF(INDEX(Techniques[Coverage],MATCH(Q8,Techniques[Name],0))>0,INDEX(Techniques[Coverage],MATCH(Q8,Techniques[Name],0)),""),"") | S8: Software Deployment Tools (T1072) | T8: =IF(S8<>"",IF(INDEX(Techniques[Coverage],MATCH(S8,Techniques[Name],0))>0,INDEX(Techniques[Coverage],MATCH(S8,Techniques[Name],0)),""),"") | U8: Data Staged (T1074) | V8: =IF(U8<>"",IF(INDEX(Techniques[Coverage],MATCH(U8,Techniques[Name],0))>0,INDEX(Techniques[Coverage],MATCH(U8,Techniques[Name],0)),""),"") | W8: Encrypted Channel (T1573) | X8: =IF(W8<>"",IF(INDEX(Techniques[Coverage],MATCH(W8,Techniques[Name],0))>0,INDEX(Techniques[Coverage],MATCH(W8,Techniques[Name],0)),""),"") | Y8: Exfiltration Over Web Service (T1567) | Z8: =IF(Y8<>"",IF(INDEX(Techniques[Coverage],MATCH(Y8,Techniques[Name],0))>0,INDEX(Techniques[Coverage],MATCH(Y8,Techniques[Name],0)),""),"") | AA8: Endpoint Denial of Service (T1499) | AB8: =IF(AA8<>"",IF(INDEX(Techniques[Coverage],MATCH(AA8,Techniques[Name],0))>0,INDEX(Techniques[Coverage],MATCH(AA8,Techniques[Name],0)),""),"")
A9: Search Open Technical Databases (T1596) | B9: =IF(A9<>"",IF(INDEX(Techniques[Coverage],MATCH(A9,Techniques[Name],0))>0,INDEX(Techniques[Coverage],MATCH(A9,Techniques[Name],0)),""),"") | C9: Stage Capabilities (T1608) | D9: =IF(C9<>"",IF(INDEX(Techniques[Coverage],MATCH(C9,Techniques[Name],0))>0,INDEX(Techniques[Coverage],MATCH(C9,Techniques[Name],0)),""),"") | E9: Supply Chain Compromise (T1195) | F9: =IF(E9<>"",IF(INDEX(Techniques[Coverage],MATCH(E9,Techniques[Name],0))>0,INDEX(Techniques[Coverage],MATCH(E9,Techniques[Name],0)),""),"") | G9: Scheduled Task/Job (T1053) | H9: =IF(G9<>"",IF(INDEX(Techniques[Coverage],MATCH(G9,Techniques[Name],0))>0,INDEX(Techniques[Coverage],MATCH(G9,Techniques[Name],0)),""),"") | I9: Create or Modify System Process (T1543) | J9: =IF(I9<>"",IF(INDEX(Techniques[Coverage],MATCH(I9,Techniques[Name],0))>0,INDEX(Techniques[Coverage],MATCH(I9,Techniques[Name],0)),""),"") | K9: Escape to Host (T1611) | L9: =IF(K9<>"",IF(INDEX(Techniques[Coverage],MATCH(K9,Techniques[Name],0))>0,INDEX(Techniques[Coverage],MATCH(K9,Techniques[Name],0)),""),"") | M9: Direct Volume Access (T1006) | N9: =IF(M9<>"",IF(INDEX(Techniques[Coverage],MATCH(M9,Techniques[Name],0))>0,INDEX(Techniques[Coverage],MATCH(M9,Techniques[Name],0)),""),"") | O9: Modify Authentication Process (T1556) | P9: =IF(O9<>"",IF(INDEX(Techniques[Coverage],MATCH(O9,Techniques[Name],0))>0,INDEX(Techniques[Coverage],MATCH(O9,Techniques[Name],0)),""),"") | Q9: Container and Resource Discovery (T1613) | R9: =IF(Q9<>"",IF(INDEX(Techniques[Coverage],MATCH(Q9,Techniques[Name],0))>0,INDEX(Techniques[Coverage],MATCH(Q9,Techniques[Name],0)),""),"") | S9: Taint Shared Content (T1080) | T9: =IF(S9<>"",IF(INDEX(Techniques[Coverage],MATCH(S9,Techniques[Name],0))>0,INDEX(Techniques[Coverage],MATCH(S9,Techniques[Name],0)),""),"") | U9: Data from Cloud Storage (T1530) | V9: =IF(U9<>"",IF(INDEX(Techniques[Coverage],MATCH(U9,Techniques[Name],0))>0,INDEX(Techniques[Coverage],MATCH(U9,Techniques[Name],0)),""),"") | W9: Fallback Channels (T1008) | X9: =IF(W9<>"",IF(INDEX(Techniques[Coverage],MATCH(W9,Techniques[Name],0))>0,INDEX(Techniques[Coverage],MATCH(W9,Techniques[Name],0)),""),"") | Y9: Scheduled Transfer (T1029) | Z9: =IF(Y9<>"",IF(INDEX(Techniques[Coverage],MATCH(Y9,Techniques[Name],0))>0,INDEX(Techniques[Coverage],MATCH(Y9,Techniques[Name],0)),""),"") | AA9: Financial Theft (T1657) | AB9: =IF(AA9<>"",IF(INDEX(Techniques[Coverage],MATCH(AA9,Techniques[Name],0))>0,INDEX(Techniques[Coverage],MATCH(AA9,Techniques[Name],0)),""),"")
A10: Search Open Websites/Domains (T1593) | B10: =IF(A10<>"",IF(INDEX(Techniques[Coverage],MATCH(A10,Techniques[Name],0))>0,INDEX(Techniques[Coverage],MATCH(A10,Techniques[Name],0)),""),"") | E10: Trusted Relationship (T1199) | F10: =IF(E10<>"",IF(INDEX(Techniques[Coverage],MATCH(E10,Techniques[Name],0))>0,INDEX(Techniques[Coverage],MATCH(E10,Techniques[Name],0)),""),"") | G10: Serverless Execution (T1648) | H10: =IF(G10<>"",IF(INDEX(Techniques[Coverage],MATCH(G10,Techniques[Name],0))>0,INDEX(Techniques[Coverage],MATCH(G10,Techniques[Name],0)),""),"") | I10: Event Triggered Execution (T1546) | J10: =IF(I10<>"",IF(INDEX(Techniques[Coverage],MATCH(I10,Techniques[Name],0))>0,INDEX(Techniques[Coverage],MATCH(I10,Techniques[Name],0)),""),"") | K10: Event Triggered Execution (T1546) | L10: =IF(K10<>"",IF(INDEX(Techniques[Coverage],MATCH(K10,Techniques[Name],0))>0,INDEX(Techniques[Coverage],MATCH(K10,Techniques[Name],0)),""),"") | M10: Domain or Tenant Policy Modification (T1484) | N10: =IF(M10<>"",IF(INDEX(Techniques[Coverage],MATCH(M10,Techniques[Name],0))>0,INDEX(Techniques[Coverage],MATCH(M10,Techniques[Name],0)),""),"") | O10: Multi-Factor Authentication Interception (T1111) | P10: =IF(O10<>"",IF(INDEX(Techniques[Coverage],MATCH(O10,Techniques[Name],0))>0,INDEX(Techniques[Coverage],MATCH(O10,Techniques[Name],0)),""),"") | Q10: Debugger Evasion (T1622) | R10: =IF(Q10<>"",IF(INDEX(Techniques[Coverage],MATCH(Q10,Techniques[Name],0))>0,INDEX(Techniques[Coverage],MATCH(Q10,Techniques[Name],0)),""),"") | S10: Use Alternate Authentication Material (T1550) | T10: =IF(S10<>"",IF(INDEX(Techniques[Coverage],MATCH(S10,Techniques[Name],0))>0,INDEX(Techniques[Coverage],MATCH(S10,Techniques[Name],0)),""),"") | U10: Data from Configuration Repository (T1602) | V10: =IF(U10<>"",IF(INDEX(Techniques[Coverage],MATCH(U10,Techniques[Name],0))>0,INDEX(Techniques[Coverage],MATCH(U10,Techniques[Name],0)),""),"") | W10: Hide Infrastructure (T1665) | X10: =IF(W10<>"",IF(INDEX(Techniques[Coverage],MATCH(W10,Techniques[Name],0))>0,INDEX(Techniques[Coverage],MATCH(W10,Techniques[Name],0)),""),"") | Y10: Transfer Data to Cloud Account (T1537) | Z10: =IF(Y10<>"",IF(INDEX(Techniques[Coverage],MATCH(Y10,Techniques[Name],0))>0,INDEX(Techniques[Coverage],MATCH(Y10,Techniques[Name],0)),""),"") | AA10: Firmware Corruption (T1495) | AB10: =IF(AA10<>"",IF(INDEX(Techniques[Coverage],MATCH(AA10,Techniques[Name],0))>0,INDEX(Techniques[Coverage],MATCH(AA10,Techniques[Name],0)),""),"")
A11: Search Victim-Owned Websites (T1594) | B11: =IF(A11<>"",IF(INDEX(Techniques[Coverage],MATCH(A11,Techniques[Name],0))>0,INDEX(Techniques[Coverage],MATCH(A11,Techniques[Name],0)),""),"") | E11: Valid Accounts (T1078) | F11: =IF(E11<>"",IF(INDEX(Techniques[Coverage],MATCH(E11,Techniques[Name],0))>0,INDEX(Techniques[Coverage],MATCH(E11,Techniques[Name],0)),""),"") | G11: Shared Modules (T1129) | H11: =IF(G11<>"",IF(INDEX(Techniques[Coverage],MATCH(G11,Techniques[Name],0))>0,INDEX(Techniques[Coverage],MATCH(G11,Techniques[Name],0)),""),"") | I11: External Remote Services (T1133) | J11: =IF(I11<>"",IF(INDEX(Techniques[Coverage],MATCH(I11,Techniques[Name],0))>0,INDEX(Techniques[Coverage],MATCH(I11,Techniques[Name],0)),""),"") | K11: Exploitation for Privilege Escalation (T1068) | L11: =IF(K11<>"",IF(INDEX(Techniques[Coverage],MATCH(K11,Techniques[Name],0))>0,INDEX(Techniques[Coverage],MATCH(K11,Techniques[Name],0)),""),"") | M11: Execution Guardrails (T1480) | N11: =IF(M11<>"",IF(INDEX(Techniques[Coverage],MATCH(M11,Techniques[Name],0))>0,INDEX(Techniques[Coverage],MATCH(M11,Techniques[Name],0)),""),"") | O11: Multi-Factor Authentication Request Generation (T1621) | P11: =IF(O11<>"",IF(INDEX(Techniques[Coverage],MATCH(O11,Techniques[Name],0))>0,INDEX(Techniques[Coverage],MATCH(O11,Techniques[Name],0)),""),"") | Q11: Device Driver Discovery (T1652) | R11: =IF(Q11<>"",IF(INDEX(Techniques[Coverage],MATCH(Q11,Techniques[Name],0))>0,INDEX(Techniques[Coverage],MATCH(Q11,Techniques[Name],0)),""),"") | U11: Data from Information Repositories (T1213) | V11: =IF(U11<>"",IF(INDEX(Techniques[Coverage],MATCH(U11,Techniques[Name],0))>0,INDEX(Techniques[Coverage],MATCH(U11,Techniques[Name],0)),""),"") | W11: Ingress Tool Transfer (T1105) | X11: =IF(W11<>"",IF(INDEX(Techniques[Coverage],MATCH(W11,Techniques[Name],0))>0,INDEX(Techniques[Coverage],MATCH(W11,Techniques[Name],0)),""),"") | AA11: Inhibit System Recovery (T1490) | AB11: =IF(AA11<>"",IF(INDEX(Techniques[Coverage],MATCH(AA11,Techniques[Name],0))>0,INDEX(Techniques[Coverage],MATCH(AA11,Techniques[Name],0)),""),"")
G12: Software Deployment Tools (T1072) | H12: =IF(G12<>"",IF(INDEX(Techniques[Coverage],MATCH(G12,Techniques[Name],0))>0,INDEX(Techniques[Coverage],MATCH(G12,Techniques[Name],0)),""),"") | I12: Hijack Execution Flow (T1574) | J12: =IF(I12<>"",IF(INDEX(Techniques[Coverage],MATCH(I12,Techniques[Name],0))>0,INDEX(Techniques[Coverage],MATCH(I12,Techniques[Name],0)),""),"") | K12: Hijack Execution Flow (T1574) | L12: =IF(K12<>"",IF(INDEX(Techniques[Coverage],MATCH(K12,Techniques[Name],0))>0,INDEX(Techniques[Coverage],MATCH(K12,Techniques[Name],0)),""),"") | M12: Exploitation for Defense Evasion (T1211) | N12: =IF(M12<>"",IF(INDEX(Techniques[Coverage],MATCH(M12,Techniques[Name],0))>0,INDEX(Techniques[Coverage],MATCH(M12,Techniques[Name],0)),""),"") | O12: Network Sniffing (T1040) | P12: =IF(O12<>"",IF(INDEX(Techniques[Coverage],MATCH(O12,Techniques[Name],0))>0,INDEX(Techniques[Coverage],MATCH(O12,Techniques[Name],0)),""),"") | Q12: Domain Trust Discovery (T1482) | R12: =IF(Q12<>"",IF(INDEX(Techniques[Coverage],MATCH(Q12,Techniques[Name],0))>0,INDEX(Techniques[Coverage],MATCH(Q12,Techniques[Name],0)),""),"") | U12: Data from Local System (T1005) | V12: =IF(U12<>"",IF(INDEX(Techniques[Coverage],MATCH(U12,Techniques[Name],0))>0,INDEX(Techniques[Coverage],MATCH(U12,Techniques[Name],0)),""),"") | W12: Multi-Stage Channels (T1104) | X12: =IF(W12<>"",IF(INDEX(Techniques[Coverage],MATCH(W12,Techniques[Name],0))>0,INDEX(Techniques[Coverage],MATCH(W12,Techniques[Name],0)),""),"") | AA12: Network Denial of Service (T1498) | AB12: =IF(AA12<>"",IF(INDEX(Techniques[Coverage],MATCH(AA12,Techniques[Name],0))>0,INDEX(Techniques[Coverage],MATCH(AA12,Techniques[Name],0)),""),"")
G13: System Services (T1569) | H13: =IF(G13<>"",IF(INDEX(Techniques[Coverage],MATCH(G13,Techniques[Name],0))>0,INDEX(Techniques[Coverage],MATCH(G13,Techniques[Name],0)),""),"") | I13: Implant Internal Image (T1525) | J13: =IF(I13<>"",IF(INDEX(Techniques[Coverage],MATCH(I13,Techniques[Name],0))>0,INDEX(Techniques[Coverage],MATCH(I13,Techniques[Name],0)),""),"") | K13: Process Injection (T1055) | L13: =IF(K13<>"",IF(INDEX(Techniques[Coverage],MATCH(K13,Techniques[Name],0))>0,INDEX(Techniques[Coverage],MATCH(K13,Techniques[Name],0)),""),"") | M13: File and Directory Permissions Modification (T1222) | N13: =IF(M13<>"",IF(INDEX(Techniques[Coverage],MATCH(M13,Techniques[Name],0))>0,INDEX(Techniques[Coverage],MATCH(M13,Techniques[Name],0)),""),"") | O13: OS Credential Dumping (T1003) | P13: =IF(O13<>"",IF(INDEX(Techniques[Coverage],MATCH(O13,Techniques[Name],0))>0,INDEX(Techniques[Coverage],MATCH(O13,Techniques[Name],0)),""),"") -> 0.25 | Q13: File and Directory Discovery (T1083) | R13: =IF(Q13<>"",IF(INDEX(Techniques[Coverage],MATCH(Q13,Techniques[Name],0))>0,INDEX(Techniques[Coverage],MATCH(Q13,Techniques[Name],0)),""),"") | U13: Data from Network Shared Drive (T1039) | V13: =IF(U13<>"",IF(INDEX(Techniques[Coverage],MATCH(U13,Techniques[Name],0))>0,INDEX(Techniques[Coverage],MATCH(U13,Techniques[Name],0)),""),"") | W13: Non-Application Layer Protocol (T1095) | X13: =IF(W13<>"",IF(INDEX(Techniques[Coverage],MATCH(W13,Techniques[Name],0))>0,INDEX(Techniques[Coverage],MATCH(W13,Techniques[Name],0)),""),"") | AA13: Resource Hijacking (T1496) | AB13: =IF(AA13<>"",IF(INDEX(Techniques[Coverage],MATCH(AA13,Techniques[Name],0))>0,INDEX(Techniques[Coverage],MATCH(AA13,Techniques[Name],0)),""),"")
G14: User Execution (T1204) | H14: =IF(G14<>"",IF(INDEX(Techniques[Coverage],MATCH(G14,Techniques[Name],0))>0,INDEX(Techniques[Coverage],MATCH(G14,Techniques[Name],0)),""),"") | I14: Modify Authentication Process (T1556) | J14: =IF(I14<>"",IF(INDEX(Techniques[Coverage],MATCH(I14,Techniques[Name],0))>0,INDEX(Techniques[Coverage],MATCH(I14,Techniques[Name],0)),""),"") | K14: Scheduled Task/Job (T1053) | L14: =IF(K14<>"",IF(INDEX(Techniques[Coverage],MATCH(K14,Techniques[Name],0))>0,INDEX(Techniques[Coverage],MATCH(K14,Techniques[Name],0)),""),"") | M14: Hide Artifacts (T1564) | N14: =IF(M14<>"",IF(INDEX(Techniques[Coverage],MATCH(M14,Techniques[Name],0))>0,INDEX(Techniques[Coverage],MATCH(M14,Techniques[Name],0)),""),"") | O14: Steal Application Access Token (T1528) | P14: =IF(O14<>"",IF(INDEX(Techniques[Coverage],MATCH(O14,Techniques[Name],0))>0,INDEX(Techniques[Coverage],MATCH(O14,Techniques[Name],0)),""),"") | Q14: Group Policy Discovery (T1615) | R14: =IF(Q14<>"",IF(INDEX(Techniques[Coverage],MATCH(Q14,Techniques[Name],0))>0,INDEX(Techniques[Coverage],MATCH(Q14,Techniques[Name],0)),""),"") | U14: Data from Removable Media (T1025) | V14: =IF(U14<>"",IF(INDEX(Techniques[Coverage],MATCH(U14,Techniques[Name],0))>0,INDEX(Techniques[Coverage],MATCH(U14,Techniques[Name],0)),""),"") | W14: Non-Standard Port (T1571) | X14: =IF(W14<>"",IF(INDEX(Techniques[Coverage],MATCH(W14,Techniques[Name],0))>0,INDEX(Techniques[Coverage],MATCH(W14,Techniques[Name],0)),""),"") | AA14: Service Stop (T1489) | AB14: =IF(AA14<>"",IF(INDEX(Techniques[Coverage],MATCH(AA14,Techniques[Name],0))>0,INDEX(Techniques[Coverage],MATCH(AA14,Techniques[Name],0)),""),"")
G15: Windows Management Instrumentation (T1047) | H15: =IF(G15<>"",IF(INDEX(Techniques[Coverage],MATCH(G15,Techniques[Name],0))>0,INDEX(Techniques[Coverage],MATCH(G15,Techniques[Name],0)),""),"") | I15: Office Application Startup (T1137) | J15: =IF(I15<>"",IF(INDEX(Techniques[Coverage],MATCH(I15,Techniques[Name],0))>0,INDEX(Techniques[Coverage],MATCH(I15,Techniques[Name],0)),""),"") | K15: Valid Accounts (T1078) | L15: =IF(K15<>"",IF(INDEX(Techniques[Coverage],MATCH(K15,Techniques[Name],0))>0,INDEX(Techniques[Coverage],MATCH(K15,Techniques[Name],0)),""),"") | M15: Hijack Execution Flow (T1574) | N15: =IF(M15<>"",IF(INDEX(Techniques[Coverage],MATCH(M15,Techniques[Name],0))>0,INDEX(Techniques[Coverage],MATCH(M15,Techniques[Name],0)),""),"") | O15: Steal Web Session Cookie (T1539) | P15: =IF(O15<>"",IF(INDEX(Techniques[Coverage],MATCH(O15,Techniques[Name],0))>0,INDEX(Techniques[Coverage],MATCH(O15,Techniques[Name],0)),""),"") | Q15: Log Enumeration (T1654) | R15: =IF(Q15<>"",IF(INDEX(Techniques[Coverage],MATCH(Q15,Techniques[Name],0))>0,INDEX(Techniques[Coverage],MATCH(Q15,Techniques[Name],0)),""),"") | U15: Email Collection (T1114) | V15: =IF(U15<>"",IF(INDEX(Techniques[Coverage],MATCH(U15,Techniques[Name],0))>0,INDEX(Techniques[Coverage],MATCH(U15,Techniques[Name],0)),""),"") | W15: Protocol Tunneling (T1572) | X15: =IF(W15<>"",IF(INDEX(Techniques[Coverage],MATCH(W15,Techniques[Name],0))>0,INDEX(Techniques[Coverage],MATCH(W15,Techniques[Name],0)),""),"") | AA15: System Shutdown/Reboot (T1529) | AB15: =IF(AA15<>"",IF(INDEX(Techniques[Coverage],MATCH(AA15,Techniques[Name],0))>0,INDEX(Techniques[Coverage],MATCH(AA15,Techniques[Name],0)),""),"")
I16: Power Settings (T1653) | J16: =IF(I16<>"",IF(INDEX(Techniques[Coverage],MATCH(I16,Techniques[Name],0))>0,INDEX(Techniques[Coverage],MATCH(I16,Techniques[Name],0)),""),"") | M16: Impair Defenses (T1562) | N16: =IF(M16<>"",IF(INDEX(Techniques[Coverage],MATCH(M16,Techniques[Name],0))>0,INDEX(Techniques[Coverage],MATCH(M16,Techniques[Name],0)),""),"") | O16: Steal or Forge Authentication Certificates (T1649) | P16: =IF(O16<>"",IF(INDEX(Techniques[Coverage],MATCH(O16,Techniques[Name],0))>0,INDEX(Techniques[Coverage],MATCH(O16,Techniques[Name],0)),""),"") | Q16: Network Service Discovery (T1046) | R16: =IF(Q16<>"",IF(INDEX(Techniques[Coverage],MATCH(Q16,Techniques[Name],0))>0,INDEX(Techniques[Coverage],MATCH(Q16,Techniques[Name],0)),""),"") | U16: Input Capture (T1056) | V16: =IF(U16<>"",IF(INDEX(Techniques[Coverage],MATCH(U16,Techniques[Name],0))>0,INDEX(Techniques[Coverage],MATCH(U16,Techniques[Name],0)),""),"") | W16: Proxy (T1090) | X16: =IF(W16<>"",IF(INDEX(Techniques[Coverage],MATCH(W16,Techniques[Name],0))>0,INDEX(Techniques[Coverage],MATCH(W16,Techniques[Name],0)),""),"")
I17: Pre-OS Boot (T1542) | J17: =IF(I17<>"",IF(INDEX(Techniques[Coverage],MATCH(I17,Techniques[Name],0))>0,INDEX(Techniques[Coverage],MATCH(I17,Techniques[Name],0)),""),"") | M17: Impersonation (T1656) | N17: =IF(M17<>"",IF(INDEX(Techniques[Coverage],MATCH(M17,Techniques[Name],0))>0,INDEX(Techniques[Coverage],MATCH(M17,Techniques[Name],0)),""),"") | O17: Steal or Forge Kerberos Tickets (T1558) | P17: =IF(O17<>"",IF(INDEX(Techniques[Coverage],MATCH(O17,Techniques[Name],0))>0,INDEX(Techniques[Coverage],MATCH(O17,Techniques[Name],0)),""),"") | Q17: Network Share Discovery (T1135) | R17: =IF(Q17<>"",IF(INDEX(Techniques[Coverage],MATCH(Q17,Techniques[Name],0))>0,INDEX(Techniques[Coverage],MATCH(Q17,Techniques[Name],0)),""),"") | U17: Screen Capture (T1113) | V17: =IF(U17<>"",IF(INDEX(Techniques[Coverage],MATCH(U17,Techniques[Name],0))>0,INDEX(Techniques[Coverage],MATCH(U17,Techniques[Name],0)),""),"") | W17: Remote Access Software (T1219) | X17: =IF(W17<>"",IF(INDEX(Techniques[Coverage],MATCH(W17,Techniques[Name],0))>0,INDEX(Techniques[Coverage],MATCH(W17,Techniques[Name],0)),""),"")
I18: Scheduled Task/Job (T1053) | J18: =IF(I18<>"",IF(INDEX(Techniques[Coverage],MATCH(I18,Techniques[Name],0))>0,INDEX(Techniques[Coverage],MATCH(I18,Techniques[Name],0)),""),"") | M18: Indicator Removal (T1070) | N18: =IF(M18<>"",IF(INDEX(Techniques[Coverage],MATCH(M18,Techniques[Name],0))>0,INDEX(Techniques[Coverage],MATCH(M18,Techniques[Name],0)),""),"") | O18: Unsecured Credentials (T1552) | P18: =IF(O18<>"",IF(INDEX(Techniques[Coverage],MATCH(O18,Techniques[Name],0))>0,INDEX(Techniques[Coverage],MATCH(O18,Techniques[Name],0)),""),"") | Q18: Network Sniffing (T1040) | R18: =IF(Q18<>"",IF(INDEX(Techniques[Coverage],MATCH(Q18,Techniques[Name],0))>0,INDEX(Techniques[Coverage],MATCH(Q18,Techniques[Name],0)),""),"") | U18: Video Capture (T1125) | V18: =IF(U18<>"",IF(INDEX(Techniques[Coverage],MATCH(U18,Techniques[Name],0))>0,INDEX(Techniques[Coverage],MATCH(U18,Techniques[Name],0)),""),"") | W18: Traffic Signaling (T1205) | X18: =IF(W18<>"",IF(INDEX(Techniques[Coverage],MATCH(W18,Techniques[Name],0))>0,INDEX(Techniques[Coverage],MATCH(W18,Techniques[Name],0)),""),"")
I19: Server Software Component (T1505) | J19: =IF(I19<>"",IF(INDEX(Techniques[Coverage],MATCH(I19,Techniques[Name],0))>0,INDEX(Techniques[Coverage],MATCH(I19,Techniques[Name],0)),""),"") | M19: Indirect Command Execution (T1202) | N19: =IF(M19<>"",IF(INDEX(Techniques[Coverage],MATCH(M19,Techniques[Name],0))>0,INDEX(Techniques[Coverage],MATCH(M19,Techniques[Name],0)),""),"") | Q19: Password Policy Discovery (T1201) | R19: =IF(Q19<>"",IF(INDEX(Techniques[Coverage],MATCH(Q19,Techniques[Name],0))>0,INDEX(Techniques[Coverage],MATCH(Q19,Techniques[Name],0)),""),"") | W19: Web Service (T1102) | X19: =IF(W19<>"",IF(INDEX(Techniques[Coverage],MATCH(W19,Techniques[Name],0))>0,INDEX(Techniques[Coverage],MATCH(W19,Techniques[Name],0)),""),"")
I20: Traffic Signaling (T1205) | J20: =IF(I20<>"",IF(INDEX(Techniques[Coverage],MATCH(I20,Techniques[Name],0))>0,INDEX(Techniques[Coverage],MATCH(I20,Techniques[Name],0)),""),"") | M20: Masquerading (T1036) | N20: =IF(M20<>"",IF(INDEX(Techniques[Coverage],MATCH(M20,Techniques[Name],0))>0,INDEX(Techniques[Coverage],MATCH(M20,Techniques[Name],0)),""),"") -> 0.1 | Q20: Peripheral Device Discovery (T1120) | R20: =IF(Q20<>"",IF(INDEX(Techniques[Coverage],MATCH(Q20,Techniques[Name],0))>0,INDEX(Techniques[Coverage],MATCH(Q20,Techniques[Name],0)),""),"")
I21: Valid Accounts (T1078) | J21: =IF(I21<>"",IF(INDEX(Techniques[Coverage],MATCH(I21,Techniques[Name],0))>0,INDEX(Techniques[Coverage],MATCH(I21,Techniques[Name],0)),""),"") | M21: Modify Authentication Process (T1556) | N21: =IF(M21<>"",IF(INDEX(Techniques[Coverage],MATCH(M21,Techniques[Name],0))>0,INDEX(Techniques[Coverage],MATCH(M21,Techniques[Name],0)),""),"") | Q21: Permission Groups Discovery (T1069) | R21: =IF(Q21<>"",IF(INDEX(Techniques[Coverage],MATCH(Q21,Techniques[Name],0))>0,INDEX(Techniques[Coverage],MATCH(Q21,Techniques[Name],0)),""),"")
M22: Modify Cloud Compute Infrastructure (T1578) | N22: =IF(M22<>"",IF(INDEX(Techniques[Coverage],MATCH(M22,Techniques[Name],0))>0,INDEX(Techniques[Coverage],MATCH(M22,Techniques[Name],0)),""),"") | Q22: Process Discovery (T1057) | R22: =IF(Q22<>"",IF(INDEX(Techniques[Coverage],MATCH(Q22,Techniques[Name],0))>0,INDEX(Techniques[Coverage],MATCH(Q22,Techniques[Name],0)),""),"")
M23: Modify Cloud Resource Hierarchy (T1666) | N23: =IF(M23<>"",IF(INDEX(Techniques[Coverage],MATCH(M23,Techniques[Name],0))>0,INDEX(Techniques[Coverage],MATCH(M23,Techniques[Name],0)),""),"") | Q23: Query Registry (T1012) | R23: =IF(Q23<>"",IF(INDEX(Techniques[Coverage],MATCH(Q23,Techniques[Name],0))>0,INDEX(Techniques[Coverage],MATCH(Q23,Techniques[Name],0)),""),"")
M24: Modify Registry (T1112) | N24: =IF(M24<>"",IF(INDEX(Techniques[Coverage],MATCH(M24,Techniques[Name],0))>0,INDEX(Techniques[Coverage],MATCH(M24,Techniques[Name],0)),""),"") | Q24: Remote System Discovery (T1018) | R24: =IF(Q24<>"",IF(INDEX(Techniques[Coverage],MATCH(Q24,Techniques[Name],0))>0,INDEX(Techniques[Coverage],MATCH(Q24,Techniques[Name],0)),""),"")
M25: Modify System Image (T1601) | N25: =IF(M25<>"",IF(INDEX(Techniques[Coverage],MATCH(M25,Techniques[Name],0))>0,INDEX(Techniques[Coverage],MATCH(M25,Techniques[Name],0)),""),"") | Q25: Software Discovery (T1518) | R25: =IF(Q25<>"",IF(INDEX(Techniques[Coverage],MATCH(Q25,Techniques[Name],0))>0,INDEX(Techniques[Coverage],MATCH(Q25,Techniques[Name],0)),""),"")
M26: Network Boundary Bridging (T1599) | N26: =IF(M26<>"",IF(INDEX(Techniques[Coverage],MATCH(M26,Techniques[Name],0))>0,INDEX(Techniques[Coverage],MATCH(M26,Techniques[Name],0)),""),"") | Q26: System Information Discovery (T1082) | R26: =IF(Q26<>"",IF(INDEX(Techniques[Coverage],MATCH(Q26,Techniques[Name],0))>0,INDEX(Techniques[Coverage],MATCH(Q26,Techniques[Name],0)),""),"")
M27: Obfuscated Files or Information (T1027) | N27: =IF(M27<>"",IF(INDEX(Techniques[Coverage],MATCH(M27,Techniques[Name],0))>0,INDEX(Techniques[Coverage],MATCH(M27,Techniques[Name],0)),""),"") -> 0.071428571 | Q27: System Location Discovery (T1614) | R27: =IF(Q27<>"",IF(INDEX(Techniques[Coverage],MATCH(Q27,Techniques[Name],0))>0,INDEX(Techniques[Coverage],MATCH(Q27,Techniques[Name],0)),""),"")
M28: Plist File Modification (T1647) | N28: =IF(M28<>"",IF(INDEX(Techniques[Coverage],MATCH(M28,Techniques[Name],0))>0,INDEX(Techniques[Coverage],MATCH(M28,Techniques[Name],0)),""),"") | Q28: System Network Configuration Discovery (T1016) | R28: =IF(Q28<>"",IF(INDEX(Techniques[Coverage],MATCH(Q28,Techniques[Name],0))>0,INDEX(Techniques[Coverage],MATCH(Q28,Techniques[Name],0)),""),"") -> 0.5
M29: Pre-OS Boot (T1542) | N29: =IF(M29<>"",IF(INDEX(Techniques[Coverage],MATCH(M29,Techniques[Name],0))>0,INDEX(Techniques[Coverage],MATCH(M29,Techniques[Name],0)),""),"") | Q29: System Network Connections Discovery (T1049) | R29: =IF(Q29<>"",IF(INDEX(Techniques[Coverage],MATCH(Q29,Techniques[Name],0))>0,INDEX(Techniques[Coverage],MATCH(Q29,Techniques[Name],0)),""),"")
M30: Process Injection (T1055) | N30: =IF(M30<>"",IF(INDEX(Techniques[Coverage],MATCH(M30,Techniques[Name],0))>0,INDEX(Techniques[Coverage],MATCH(M30,Techniques[Name],0)),""),"") | Q30: System Owner/User Discovery (T1033) | R30: =IF(Q30<>"",IF(INDEX(Techniques[Coverage],MATCH(Q30,Techniques[Name],0))>0,INDEX(Techniques[Coverage],MATCH(Q30,Techniques[Name],0)),""),"")
M31: Reflective Code Loading (T1620) | N31: =IF(M31<>"",IF(INDEX(Techniques[Coverage],MATCH(M31,Techniques[Name],0))>0,INDEX(Techniques[Coverage],MATCH(M31,Techniques[Name],0)),""),"") | Q31: System Service Discovery (T1007) | R31: =IF(Q31<>"",IF(INDEX(Techniques[Coverage],MATCH(Q31,Techniques[Name],0))>0,INDEX(Techniques[Coverage],MATCH(Q31,Techniques[Name],0)),""),"")
M32: Rogue Domain Controller (T1207) | N32: =IF(M32<>"",IF(INDEX(Techniques[Coverage],MATCH(M32,Techniques[Name],0))>0,INDEX(Techniques[Coverage],MATCH(M32,Techniques[Name],0)),""),"") | Q32: System Time Discovery (T1124) | R32: =IF(Q32<>"",IF(INDEX(Techniques[Coverage],MATCH(Q32,Techniques[Name],0))>0,INDEX(Techniques[Coverage],MATCH(Q32,Techniques[Name],0)),""),"")
M33: Rootkit (T1014) | N33: =IF(M33<>"",IF(INDEX(Techniques[Coverage],MATCH(M33,Techniques[Name],0))>0,INDEX(Techniques[Coverage],MATCH(M33,Techniques[Name],0)),""),"") -> 1 | Q33: Virtualization/Sandbox Evasion (T1497) | R33: =IF(Q33<>"",IF(INDEX(Techniques[Coverage],MATCH(Q33,Techniques[Name],0))>0,INDEX(Techniques[Coverage],MATCH(Q33,Techniques[Name],0)),""),"")
M34: Subvert Trust Controls (T1553) | N34: =IF(M34<>"",IF(INDEX(Techniques[Coverage],MATCH(M34,Techniques[Name],0))>0,INDEX(Techniques[Coverage],MATCH(M34,Techniques[Name],0)),""),"")
M35: System Binary Proxy Execution (T1218) | N35: =IF(M35<>"",IF(INDEX(Techniques[Coverage],MATCH(M35,Techniques[Name],0))>0,INDEX(Techniques[Coverage],MATCH(M35,Techniques[Name],0)),""),"")
M36: System Script Proxy Execution (T1216) | N36: =IF(M36<>"",IF(INDEX(Techniques[Coverage],MATCH(M36,Techniques[Name],0))>0,INDEX(Techniques[Coverage],MATCH(M36,Techniques[Name],0)),""),"")
M37: Template Injection (T1221) | N37: =IF(M37<>"",IF(INDEX(Techniques[Coverage],MATCH(M37,Techniques[Name],0))>0,INDEX(Techniques[Coverage],MATCH(M37,Techniques[Name],0)),""),"")
M38: Traffic Signaling (T1205) | N38: =IF(M38<>"",IF(INDEX(Techniques[Coverage],MATCH(M38,Techniques[Name],0))>0,INDEX(Techniques[Coverage],MATCH(M38,Techniques[Name],0)),""),"")
M39: Trusted Developer Utilities Proxy Execution (T1127) | N39: =IF(M39<>"",IF(INDEX(Techniques[Coverage],MATCH(M39,Techniques[Name],0))>0,INDEX(Techniques[Coverage],MATCH(M39,Techniques[Name],0)),""),"")
M40: Unused/Unsupported Cloud Regions (T1535) | N40: =IF(M40<>"",IF(INDEX(Techniques[Coverage],MATCH(M40,Techniques[Name],0))>0,INDEX(Techniques[Coverage],MATCH(M40,Techniques[Name],0)),""),"")
...

Sheet Detection Rules
A1: Source | B1: Use Case | C1: Rule Description | D1: Is Active | E1: Attack1 | F1: Attack2 | G1: Attack3 | H1: Attack4 | I1: Attack5 | J1: Attack6 | K1: Attack7 | L1: Attack8 | M1: Attack9 | N1: Attack10
A2: IBM Qradar | B2: Detection Rule 1 | D2: yes | E2: Masquerading (T1036) | F2: Internet Connection Discovery (T1016.001) | G2: NTDS (T1003.003) | H2: Active Scanning (T1595)
A3: Microsoft Sentinel | B3: Detection Rule 2 | D3: yes | E3: Rootkit (T1014) | F3: Traffic Duplication (T1020.001) | G3: AppleScript (T1059.002)
A4: Microsoft Defender | B4: Detection Rule 3 | D4: yes | E4: OS Credential Dumping (T1003) | F4: Rootkit (T1014)
A5: Crowdstrike EDR | B5: EDR Rule 1 | D5: yes | E5: HTML Smuggling (T1027.006) | F5: Application Window Discovery (T1010)

Sheet Mitre Techniques
A1: Technique | B1: ID | C1: Name | D1: Tactics | E1: Data Sources | F1: Data Sources No. | G1: Data Sources Available | H1: No. of Sub Techniques | I1: Detection Rules for Technique | J1: Detection Rules for SubTech | K1: Min. Detection Rules | L1: Detection Rules Modifier | M1: Expected Detection Rules | N1: Detection Rules | O1: Coverage | P1: Technique Status | Q1: Notes | R1: ID Checks | S1: Error Checks | T1: platforms | U1: description | V1: detection | W1: is sub-technique | X1: sub-technique of
A2: T1001 | B2: T1001 | C2: Data Obfuscation (T1001) | D2: Command and Control | E2: Network Traffic: Network Traffic Content | F2: =LEN(E2)-LEN(SUBSTITUTE(E2,",",""))+1 -> 1 | G2: {=SUM(IF(ISERROR(FIND(Sources[Data Source],Techniques[[#This Row],[Data Sources]])),0,1)*IF(Sources[Available]="yes",1,0))} -> 1 | H2: {=IF(Techniques[[#This Row],[Technique]]=Techniques[[#This Row],[ID]],SUM(IF(Techniques[[#This Row],[ID]]=Techniques[Technique],1,0))-1,"")} -> 3 | I2: {=IF(SUM(IF($C2=Detections[],IF(Detections[Is Active]="yes",1,0),0))>0,SUM(IF($C2=Detections[],IF(Detections[Is Active]="yes",1,0),0)),"")} | J2: {=IF(IF(ISNUMBER(Techniques[[#This Row],[No. of Sub Techniques]]), Techniques[[#This Row],[No. of Sub Techniques]]>0,FALSE),SUM(IF(Techniques[[#This Row],[Technique]]=Techniques[Technique],Techniques[Detection Rules for Technique],0))-IF(ISNUMBER(Techniques[[#This Row],[Detection Rules for Technique]]),Techniques[[#This Row],[Detection Rules for Technique]],0),"")} -> 0 | K2: =IF(AND(ISNUMBER(Techniques[[#This Row],[No. of Sub Techniques]]),Techniques[[#This Row],[No. of Sub Techniques]]>1),Techniques[No. of Sub Techniques],1) -> 3 | M2: {=Techniques[[#This Row],[Min. Detection Rules]]+IF(IF(ISNUMBER(Techniques[[#This Row],[No. of Sub Techniques]]),Techniques[[#This Row],[No. of Sub Techniques]]>0,FALSE),SUM(IF(Techniques[[#This Row],[Technique]]=Techniques[Technique],Techniques[Detection Rules Modifier],0)),Techniques[[#This Row],[Detection Rules Modifier]])} -> 3 | N2: =IF(ISNUMBER(Techniques[[#This Row],[Detection Rules for Technique]]),Techniques[[#This Row],[Detection Rules for Technique]],0)+IF(ISNUMBER(Techniques[[#This Row],[Detection Rules for SubTech]]),Techniques[[#This Row],[Detection Rules for SubTech]],0) -> 0 | O2: =IF(Techniques[[#This Row],[Detection Rules]]>=Techniques[[#This Row],[Expected Detection Rules]],1,Techniques[[#This Row],[Detection Rules]]/Techniques[[#This Row],[Expected Detection Rules]]) -> 0 | P2: =IF(Techniques[[#This Row],[Expected Detection Rules]]<=0,"disabled",IF(Techniques[[#This Row],[Data Sources Available]]>0, IF(Techniques[[#This Row],[Detection Rules]]>0,"detect","no detect"),IF(Techniques[[#This Row],[Detection Rules]]>0,"inconsistent","no sources"))) -> no detect | S2: =IF(Techniques[[#This Row],[Expected Detection Rules]]<0,"expected detection rules negative!",IF(Techniques[[#This Row],[Detection Rules]]>Techniques[[#This Row],[Expected Detection Rules]],"more detection rules than expected!",IF(AND(IF(ISNUMBER(Techniques[[#This Row],[Detection Rules for Technique]]),Techniques[[#This Row],[Detection Rules for Technique]]>0,FALSE),IF(ISNUMBER(Techniques[[#This Row],[No. of Sub Techniques]]),Techniques[[#This Row],[No. of Sub Techniques]]>0,FALSE)),IF(Techniques[[#This Row],[Detection Rules for Technique]] > IF(ISNUMBER(Techniques[[#This Row],[Detection Rules Modifier]]),Techniques[[#This Row],[Detection Rules Modifier]],0), "modifier should be increased for the technique", ""),""))) | T2: Linux, Windows, macOS | U2: Adversaries may obfuscate command and control traffic to make it more difficult to detect.(Citation: Bitdefender FunnyDream Campaign November 2020) Command and control (C2) communications are hidden (but not necessarily encrypted) in an attempt to make the content more difficult to discover or decipher and to make the communication less conspicuous and hide commands from being seen. This encompasses many methods, such as adding junk data to protocol traffic, using steganography, or impersonating legitimate protocols. | V2: Analyze network data for uncommon data flows (e.g., a client sending significantly more data than it receives from a server). Processes utilizing the network that do not normally have network communication or have never been seen before are suspicious. Analyze packet contents to detect communications that do not follow the expected protocol behavior for the port that is being used. (Citation: University of Birmingham C2) | W2: FALSE
A3: T1001 | B3: T1001.001 | C3: Junk Data (T1001.001) | D3: Command and Control | E3: Network Traffic: Network Traffic Content | F3: =LEN(E3)-LEN(SUBSTITUTE(E3,",",""))+1 -> 1 | G3: {=SUM(IF(ISERROR(FIND(Sources[Data Source],Techniques[[#This Row],[Data Sources]])),0,1)*IF(Sources[Available]="yes",1,0))} -> 1 | H3: {=IF(Techniques[[#This Row],[Technique]]=Techniques[[#This Row],[ID]],SUM(IF(Techniques[[#This Row],[ID]]=Techniques[Technique],1,0))-1,"")} | I3: {=IF(SUM(IF($C3=Detections[],IF(Detections[Is Active]="yes",1,0),0))>0,SUM(IF($C3=Detections[],IF(Detections[Is Active]="yes",1,0),0)),"")} | J3: {=IF(IF(ISNUMBER(Techniques[[#This Row],[No. of Sub Techniques]]), Techniques[[#This Row],[No. of Sub Techniques]]>0,FALSE),SUM(IF(Techniques[[#This Row],[Technique]]=Techniques[Technique],Techniques[Detection Rules for Technique],0))-IF(ISNUMBER(Techniques[[#This Row],[Detection Rules for Technique]]),Techniques[[#This Row],[Detection Rules for Technique]],0),"")} | K3: =IF(AND(ISNUMBER(Techniques[[#This Row],[No. of Sub Techniques]]),Techniques[[#This Row],[No. of Sub Techniques]]>1),Techniques[No. of Sub Techniques],1) -> 1 | M3: {=Techniques[[#This Row],[Min. Detection Rules]]+IF(IF(ISNUMBER(Techniques[[#This Row],[No. of Sub Techniques]]),Techniques[[#This Row],[No. of Sub Techniques]]>0,FALSE),SUM(IF(Techniques[[#This Row],[Technique]]=Techniques[Technique],Techniques[Detection Rules Modifier],0)),Techniques[[#This Row],[Detection Rules Modifier]])} -> 1 | N3: =IF(ISNUMBER(Techniques[[#This Row],[Detection Rules for Technique]]),Techniques[[#This Row],[Detection Rules for Technique]],0)+IF(ISNUMBER(Techniques[[#This Row],[Detection Rules for SubTech]]),Techniques[[#This Row],[Detection Rules for SubTech]],0) -> 0 | O3: =IF(Techniques[[#This Row],[Detection Rules]]>=Techniques[[#This Row],[Expected Detection Rules]],1,Techniques[[#This Row],[Detection Rules]]/Techniques[[#This Row],[Expected Detection Rules]]) -> 0 | P3: =IF(Techniques[[#This Row],[Expected Detection Rules]]<=0,"disabled",IF(Techniques[[#This Row],[Data Sources Available]]>0, IF(Techniques[[#This Row],[Detection Rules]]>0,"detect","no detect"),IF(Techniques[[#This Row],[Detection Rules]]>0,"inconsistent","no sources"))) -> no detect | S3: =IF(Techniques[[#This Row],[Expected Detection Rules]]<0,"expected detection rules negative!",IF(Techniques[[#This Row],[Detection Rules]]>Techniques[[#This Row],[Expected Detection Rules]],"more detection rules than expected!",IF(AND(IF(ISNUMBER(Techniques[[#This Row],[Detection Rules for Technique]]),Techniques[[#This Row],[Detection Rules for Technique]]>0,FALSE),IF(ISNUMBER(Techniques[[#This Row],[No. of Sub Techniques]]),Techniques[[#This Row],[No. of Sub Techniques]]>0,FALSE)),IF(Techniques[[#This Row],[Detection Rules for Technique]] > IF(ISNUMBER(Techniques[[#This Row],[Detection Rules Modifier]]),Techniques[[#This Row],[Detection Rules Modifier]],0), "modifier should be increased for the technique", ""),""))) | T3: Linux, Windows, macOS | U3: Adversaries may add junk data to protocols used for command and control to make detection more difficult.(Citation: FireEye SUNBURST Backdoor December 2020) By adding random or meaningless data to the protocols used for command and control, adversaries can prevent trivial methods for decoding, deciphering, or otherwise analyzing the traffic. Examples may include appending/prepending data with junk characters or writing junk characters between significant characters. | V3: Analyze network data for uncommon data flows (e.g., a client sending significantly more data than it receives from a server). Processes utilizing the network that do not normally have network communication or have never been seen before are suspicious. Analyze packet contents to detect communications that do not follow the expected protocol behavior for the port that is being used.(Citation: University of Birmingham C2) | W3: TRUE | X3: T1001
A4: T1001 | B4: T1001.002 | C4: Steganography (T1001.002) | D4: Command and Control | E4: Network Traffic: Network Traffic Content | F4: =LEN(E4)-LEN(SUBSTITUTE(E4,",",""))+1 -> 1 | G4: {=SUM(IF(ISERROR(FIND(Sources[Data Source],Techniques[[#This Row],[Data Sources]])),0,1)*IF(Sources[Available]="yes",1,0))} -> 1 | H4: {=IF(Techniques[[#This Row],[Technique]]=Techniques[[#This Row],[ID]],SUM(IF(Techniques[[#This Row],[ID]]=Techniques[Technique],1,0))-1,"")} | I4: {=IF(SUM(IF($C4=Detections[],IF(Detections[Is Active]="yes",1,0),0))>0,SUM(IF($C4=Detections[],IF(Detections[Is Active]="yes",1,0),0)),"")} | J4: {=IF(IF(ISNUMBER(Techniques[[#This Row],[No. of Sub Techniques]]), Techniques[[#This Row],[No. of Sub Techniques]]>0,FALSE),SUM(IF(Techniques[[#This Row],[Technique]]=Techniques[Technique],Techniques[Detection Rules for Technique],0))-IF(ISNUMBER(Techniques[[#This Row],[Detection Rules for Technique]]),Techniques[[#This Row],[Detection Rules for Technique]],0),"")} | K4: =IF(AND(ISNUMBER(Techniques[[#This Row],[No. of Sub Techniques]]),Techniques[[#This Row],[No. of Sub Techniques]]>1),Techniques[No. of Sub Techniques],1) -> 1 | M4: {=Techniques[[#This Row],[Min. Detection Rules]]+IF(IF(ISNUMBER(Techniques[[#This Row],[No. of Sub Techniques]]),Techniques[[#This Row],[No. of Sub Techniques]]>0,FALSE),SUM(IF(Techniques[[#This Row],[Technique]]=Techniques[Technique],Techniques[Detection Rules Modifier],0)),Techniques[[#This Row],[Detection Rules Modifier]])} -> 1 | N4: =IF(ISNUMBER(Techniques[[#This Row],[Detection Rules for Technique]]),Techniques[[#This Row],[Detection Rules for Technique]],0)+IF(ISNUMBER(Techniques[[#This Row],[Detection Rules for SubTech]]),Techniques[[#This Row],[Detection Rules for SubTech]],0) -> 0 | O4: =IF(Techniques[[#This Row],[Detection Rules]]>=Techniques[[#This Row],[Expected Detection Rules]],1,Techniques[[#This Row],[Detection Rules]]/Techniques[[#This Row],[Expected Detection Rules]]) -> 0 | P4: =IF(Techniques[[#This Row],[Expected Detection Rules]]<=0,"disabled",IF(Techniques[[#This Row],[Data Sources Available]]>0, IF(Techniques[[#This Row],[Detection Rules]]>0,"detect","no detect"),IF(Techniques[[#This Row],[Detection Rules]]>0,"inconsistent","no sources"))) -> no detect | S4: =IF(Techniques[[#This Row],[Expected Detection Rules]]<0,"expected detection rules negative!",IF(Techniques[[#This Row],[Detection Rules]]>Techniques[[#This Row],[Expected Detection Rules]],"more detection rules than expected!",IF(AND(IF(ISNUMBER(Techniques[[#This Row],[Detection Rules for Technique]]),Techniques[[#This Row],[Detection Rules for Technique]]>0,FALSE),IF(ISNUMBER(Techniques[[#This Row],[No. of Sub Techniques]]),Techniques[[#This Row],[No. of Sub Techniques]]>0,FALSE)),IF(Techniques[[#This Row],[Detection Rules for Technique]] > IF(ISNUMBER(Techniques[[#This Row],[Detection Rules Modifier]]),Techniques[[#This Row],[Detection Rules Modifier]],0), "modifier should be increased for the technique", ""),""))) | T4: Linux, Windows, macOS | U4: Adversaries may use steganographic techniques to hide command and control traffic to make detection efforts more difficult. Steganographic techniques can be used to hide data in digital messages that are transferred between systems. This hidden information can be used for command and control of compromised systems. In some cases, the passing of files embedded using steganography, such as image or document files, can be used for command and control. | V4: Analyze network data for uncommon data flows (e.g., a client sending significantly more data than it receives from a server). Processes utilizing the network that do not normally have network communication or have never been seen before are suspicious. Analyze packet contents to detect communications that do not follow the expected protocol behavior for the port that is being used.(Citation: University of Birmingham C2) | W4: TRUE | X4: T1001
